Workbook

Sheet Dashboard
A1: Strength Training
J2: % | K2: Leg Extension | L2: Incline Pec Fly | M2: Lateral Raise | N2: Hammer Grip Row | O2: Pronated Lat Pulldown | P2: Strict Row | Q2: Hammer Curl | R2: Cable Curl
A3: Lift | B3: Weight Lifted | C3: Reps | D3: Estimated 1RM | E3: Training Max (95%) | G3: Programming | J3: 65 | K3: =IF($E$8="","",CEILING($E$8*$J3/100, 2.5)) -> 42.5 | L3: =IF($E$9="","",CEILING($E$9*$J3/100, 2.5)) -> 42.5 | M3: =IF($E$10="","",CEILING($E$10*$J3/100, 2.5)) -> 42.5 | N3: =IF($E$11="","",CEILING($E$11*$J3/100, 2.5)) -> 42.5 | O3: =IF($E$12="","",CEILING($E$12*$J3/100, 2.5)) -> 42.5 | P3: =IF($E$13="","",CEILING($E$13*$J3/100, 2.5)) -> 42.5 | Q3: =IF($E$14="","",CEILING($E$14*$J3/100, 2.5)) -> 42.5 | R3: =IF($E$15="","",CEILING($E$15*$J3/100, 2.5)) -> 42.5
A4: Back Squat | B4: 100 | C4: 1 | D4: =IF(C4=1, B4, B4*(1+0.0333*C4)) -> 100 | E4: =D4*0.95 -> 95 | G4: Week | H4: % | I4: Sets | J4: 67.5 | K4: =IF($E$8="","",CEILING($E$8*$J4/100, 2.5)) -> 45 | L4: =IF($E$9="","",CEILING($E$9*$J4/100, 2.5)) -> 45 | M4: =IF($E$10="","",CEILING($E$10*$J4/100, 2.5)) -> 45 | N4: =IF($E$11="","",CEILING($E$11*$J4/100, 2.5)) -> 45 | O4: =IF($E$12="","",CEILING($E$12*$J4/100, 2.5)) -> 45 | P4: =IF($E$13="","",CEILING($E$13*$J4/100, 2.5)) -> 45 | Q4: =IF($E$14="","",CEILING($E$14*$J4/100, 2.5)) -> 45 | R4: =IF($E$15="","",CEILING($E$15*$J4/100, 2.5)) -> 45
A5: Bench Press | B5: 30 | C5: 12 | D5: =IF(C5=1, B5, B5*(1+0.0333*C5)) -> 41.988 | E5: =D5*0.95 -> 39.8886 | G5: 1 | H5: 75 | I5: 3 | J5: 70 | K5: =IF($E$8="","",CEILING($E$8*$J5/100, 2.5)) -> 45 | L5: =IF($E$9="","",CEILING($E$9*$J5/100, 2.5)) -> 45 | M5: =IF($E$10="","",CEILING($E$10*$J5/100, 2.5)) -> 45 | N5: =IF($E$11="","",CEILING($E$11*$J5/100, 2.5)) -> 45 | O5: =IF($E$12="","",CEILING($E$12*$J5/100, 2.5)) -> 45 | P5: =IF($E$13="","",CEILING($E$13*$J5/100, 2.5)) -> 45 | Q5: =IF($E$14="","",CEILING($E$14*$J5/100, 2.5)) -> 45 | R5: =IF($E$15="","",CEILING($E$15*$J5/100, 2.5)) -> 45
A6: Standing OHP | B6: 30 | C6: 1 | D6: =IF(C6=1, B6, B6*(1+0.0333*C6)) -> 30 | E6: =D6*0.95 -> 28.5 | G6: 2 | H6: 80 | I6: 3 | J6: 72.5 | K6: =IF($E$8="","",CEILING($E$8*$J6/100, 2.5)) -> 47.5 | L6: =IF($E$9="","",CEILING($E$9*$J6/100, 2.5)) -> 47.5 | M6: =IF($E$10="","",CEILING($E$10*$J6/100, 2.5)) -> 47.5 | N6: =IF($E$11="","",CEILING($E$11*$J6/100, 2.5)) -> 47.5 | O6: =IF($E$12="","",CEILING($E$12*$J6/100, 2.5)) -> 47.5 | P6: =IF($E$13="","",CEILING($E$13*$J6/100, 2.5)) -> 47.5 | Q6: =IF($E$14="","",CEILING($E$14*$J6/100, 2.5)) -> 47.5 | R6: =IF($E$15="","",CEILING($E$15*$J6/100, 2.5)) -> 47.5
A7: Deadlift | B7: 140 | C7: 1 | D7: =IF(C7=1, B7, B7*(1+0.0333*C7)) -> 140 | E7: =D7*0.95 -> 133 | G7: 3 | H7: 82.5 | I7: 3 | J7: 75 | K7: =IF($E$8="","",CEILING($E$8*$J7/100, 2.5)) -> 47.5 | L7: =IF($E$9="","",CEILING($E$9*$J7/100, 2.5)) -> 47.5 | M7: =IF($E$10="","",CEILING($E$10*$J7/100, 2.5)) -> 47.5 | N7: =IF($E$11="","",CEILING($E$11*$J7/100, 2.5)) -> 47.5 | O7: =IF($E$12="","",CEILING($E$12*$J7/100, 2.5)) -> 47.5 | P7: =IF($E$13="","",CEILING($E$13*$J7/100, 2.5)) -> 47.5 | Q7: =IF($E$14="","",CEILING($E$14*$J7/100, 2.5)) -> 47.5 | R7: =IF($E$15="","",CEILING($E$15*$J7/100, 2.5)) -> 47.5
A8: Leg Extension | B8: 50 | C8: 10 | D8: =IF(C8=1, B8, B8*(1+0.0333*C8)) -> 66.65 | E8: =D8*0.95 -> 63.3175 | G8: 4 | H8: 85 | I8: 4 | J8: 3
A9: Incline Pec Fly | B9: 50 | C9: 10 | D9: =IF(C9=1, B9, B9*(1+0.0333*C9)) -> 66.65 | E9: =D9*0.95 -> 63.3175 | G9: 5 | H9: 87.5 | I9: 3 | J9: 12
A10: Lateral Raise | B10: 50 | C10: 10 | D10: =IF(C10=1, B10, B10*(1+0.0333*C10)) -> 66.65 | E10: =D10*0.95 -> 63.3175 | G10: 6 | H10: 60 | I10: 3 | J10: 10
A11: Hammer Grip Row | B11: 50 | C11: 10 | D11: =IF(C11=1, B11, B11*(1+0.0333*C11)) -> 66.65 | E11: =D11*0.95 -> 63.3175 | G11: 7 | H11: 65 | I11: 3 | J11: 8
A12: Pronated Lat Pulldown | B12: 50 | C12: 10 | D12: =IF(C12=1, B12, B12*(1+0.0333*C12)) -> 66.65 | E12: =D12*0.95 -> 63.3175 | G12: 8 | H12: 65 | I12: 3 | J12: 6
A13: Strict Row | B13: 50 | C13: 10 | D13: =IF(C13=1, B13, B13*(1+0.0333*C13)) -> 66.65 | E13: =D13*0.95 -> 63.3175 | G13: 9 | H13: 85 | I13: 3 | J13: 5
A14: Hammer Curl | B14: 50 | C14: 10 | D14: =IF(C14=1, B14, B14*(1+0.0333*C14)) -> 66.65 | E14: =D14*0.95 -> 63.3175 | G14: 10 | H14: 90 | I14: 4 | J14: 3
A15: Cable Curl | B15: 50 | C15: 10 | D15: =IF(C15=1, B15, B15*(1+0.0333*C15)) -> 66.65 | E15: =D15*0.95 -> 63.3175 | G15: 11 | H15: 92.5 | I15: 3 | J15: 12
G16: 12 | H16: 95 | I16: 3 | J16: 10
A18: Percent | B18: Squat | C18: Bench | D18: OHP | E18: Deadlift
A19: 40 | B19: =CEILING($E$4*($A19/100), 5) -> 40 | C19: =CEILING($E$5*($A19/100), 5) -> 20 | D19: =CEILING($E$6*($A19/100), 5) -> 15 | E19: =CEILING($E$7*($A19/100), 5) -> 55
A20: 45 | B20: =CEILING($E$4*($A20/100), 5) -> 45 | C20: =CEILING($E$5*($A20/100), 5) -> 20 | D20: =CEILING($E$6*($A20/100), 5) -> 15 | E20: =CEILING($E$7*($A20/100), 5) -> 60
A21: 50 | B21: =CEILING($E$4*($A21/100), 5) -> 50 | C21: =CEILING($E$5*($A21/100), 5) -> 20 | D21: =CEILING($E$6*($A21/100), 5) -> 15 | E21: =CEILING($E$7*($A21/100), 5) -> 70
A22: 55 | B22: =CEILING($E$4*($A22/100), 5) -> 55 | C22: =CEILING($E$5*($A22/100), 5) -> 25 | D22: =CEILING($E$6*($A22/100), 5) -> 20 | E22: =CEILING($E$7*($A22/100), 5) -> 75
A23: 60 | B23: =CEILING($E$4*($A23/100), 5) -> 60 | C23: =CEILING($E$5*($A23/100), 5) -> 25 | D23: =CEILING($E$6*($A23/100), 5) -> 20 | E23: =CEILING($E$7*($A23/100), 5) -> 80
A24: 65 | B24: =CEILING($E$4*($A24/100), 5) -> 65 | C24: =CEILING($E$5*($A24/100), 5) -> 30 | D24: =CEILING($E$6*($A24/100), 5) -> 20 | E24: =CEILING($E$7*($A24/100), 5) -> 90
A25: 70 | B25: =CEILING($E$4*($A25/100), 5) -> 70 | C25: =CEILING($E$5*($A25/100), 5) -> 30 | D25: =CEILING($E$6*($A25/100), 5) -> 20 | E25: =CEILING($E$7*($A25/100), 5) -> 95
A26: 72.5 | B26: =CEILING($E$4*($A26/100), 5) -> 70 | C26: =CEILING($E$5*($A26/100), 5) -> 30 | D26: =CEILING($E$6*($A26/100), 5) -> 25 | E26: =CEILING($E$7*($A26/100), 5) -> 100
A27: 75 | B27: =CEILING($E$4*($A27/100), 5) -> 75 | C27: =CEILING($E$5*($A27/100), 5) -> 30 | D27: =CEILING($E$6*($A27/100), 5) -> 25 | E27: =CEILING($E$7*($A27/100), 5) -> 100
A28: 77.5 | B28: =CEILING($E$4*($A28/100), 5) -> 75 | C28: =CEILING($E$5*($A28/100), 5) -> 35 | D28: =CEILING($E$6*($A28/100), 5) -> 25 | E28: =CEILING($E$7*($A28/100), 5) -> 105
A29: 79 | B29: =CEILING($E$4*($A29/100), 5) -> 80 | C29: =CEILING($E$5*($A29/100), 5) -> 35 | D29: =CEILING($E$6*($A29/100), 5) -> 25 | E29: =CEILING($E$7*($A29/100), 5) -> 110
A30: 80 | B30: =CEILING($E$4*($A30/100), 5) -> 80 | C30: =CEILING($E$5*($A30/100), 5) -> 35 | D30: =CEILING($E$6*($A30/100), 5) -> 25 | E30: =CEILING($E$7*($A30/100), 5) -> 110
... A40: 100 | B40: =CEILING($E$4*($A40/100), 5) -> 95 | C40: =CEILING($E$5*($A40/100), 5) -> 40 | D40: =CEILING($E$6*($A40/100), 5) -> 30 | E40: =CEILING($E$7*($A40/100), 5) -> 135
A42: Accessory Exercise | B42: Weight | C42: Reps | D42: Estimated 1RM | E42: Training Max (95%)
A43: Leg Extension | B43: 55 | C43: 12 | D43: =IF(OR(B43="",C43=""),"",ROUND(B43*(1+C43/30),1)) -> 77 | E43: =IF(D43="","",ROUND(D43*0.95,1)) -> 73.2
A44: Incline Pec Fly | B44: 10 | C44: 8 | D44: =IF(OR(B44="",C44=""),"",ROUND(B44*(1+C44/30),1)) -> 12.7 | E44: =IF(D44="","",ROUND(D44*0.95,1)) -> 12.1
A45: Lateral Raise | D45: =IF(OR(B45="",C45=""),"",ROUND(B45*(1+C45/30),1)) | E45: =IF(D45="","",ROUND(D45*0.95,1))
A46: Hammer Grip Row | B46: 80 | C46: 12 | D46: =IF(OR(B46="",C46=""),"",ROUND(B46*(1+C46/30),1)) -> 112 | E46: =IF(D46="","",ROUND(D46*0.95,1)) -> 106.4
A47: Pronated Lat Pulldown | B47: 40 | C47: 12 | D47: =IF(OR(B47="",C47=""),"",ROUND(B47*(1+C47/30),1)) -> 56 | E47: =IF(D47="","",ROUND(D47*0.95,1)) -> 53.2
A48: Strict Row | B48: 40 | C48: 8 | D48: =IF(OR(B48="",C48=""),"",ROUND(B48*(1+C48/30),1)) -> 50.7 | E48: =IF(D48="","",ROUND(D48*0.95,1)) -> 48.2
A49: Hammer Curl | B49: 17.5 | C49: 8 | D49: =IF(OR(B49="",C49=""),"",ROUND(B49*(1+C49/30),1)) -> 22.2 | E49: =IF(D49="","",ROUND(D49*0.95,1)) -> 21.1
A50: Cable Curl | B50: 38.25 | C50: 12 | D50: =IF(OR(B50="",C50=""),"",ROUND(B50*(1+C50/30),1)) -> 53.6 | E50: =IF(D50="","",ROUND(D50*0.95,1)) -> 50.9

Sheet Week 1
A1: Week 1
A3: TUESDAY – PUSH
A4: Exercise | B4: Working Set | C4: Target Kg | D4: Reps | E4: RPE | F4: Notes
A5: Back Squat | B5: Set 1 | C5: =Dashboard!B27 -> 75 | D5: 8
B6: Set 2 | C6: =Dashboard!B27 -> 75 | D6: 8
B7: Set 3 | C7: =Dashboard!B27 -> 75 | D7: 8
A9: Bench Press | B9: Set 1 | C9: =Dashboard!C27 -> 30 | D9: 8
B10: Set 2 | C10: =Dashboard!C27 -> 30 | D10: 8
B11: Set 3 | C11: =Dashboard!C27 -> 30 | D11: 8
A13: Standing OHP | B13: Set 1 | C13: =Dashboard!D27 -> 25 | D13: 8
B14: Set 2 | C14: =Dashboard!D27 -> 25 | D14: 8
B15: Set 3 | C15: =Dashboard!D27 -> 25 | D15: 8
A17: Leg Extension | B17: Set 1 | C17: =Dashboard!K3 -> 42.5 | D17: 10-12
B18: Set 2 | C18: =Dashboard!K3 -> 42.5 | D18: 10-12
B19: Set 3 | C19: =Dashboard!K3 -> 42.5 | D19: 10-12
A21: Incline Pec Fly | B21: Set 1 | C21: =Dashboard!L3 -> 42.5 | D21: 10-12
B22: Set 2 | C22: =Dashboard!L3 -> 42.5 | D22: 10-12
B23: Set 3 | C23: =Dashboard!L3 -> 42.5 | D23: 10-12
A25: Lateral Raise | B25: Set 1 | C25: =Dashboard!M3 -> 42.5 | D25: 10-12
B26: Set 2 | C26: =Dashboard!M3 -> 42.5 | D26: 10-12
B27: Set 3 | C27: =Dashboard!M3 -> 42.5 | D27: 10-12
A30: THURSDAY – PULL
A31: Exercise | B31: Working Set | C31: Target Kg | D31: Reps | E31: RPE | F31: Notes
A32: Deadlift | B32: Set 1 | C32: =Dashboard!E27 -> 100 | D32: 8
B33: Set 2 | C33: =Dashboard!E27 -> 100 | D33: 8
B34: Set 3 | C34: =Dashboard!E27 -> 100 | D34: 8
A36: Hammer Grip Row | B36: Set 1 | C36: =Dashboard!N3 -> 42.5 | D36: 10-12
B37: Set 2 | C37: =Dashboard!N3 -> 42.5 | D37: 10-12
B38: Set 3 | C38: =Dashboard!N3 -> 42.5 | D38: 10-12
A40: Pronated Lat Pulldown | B40: Set 1 | C40: =Dashboard!O3 -> 42.5 | D40: 10-12
B41: Set 2 | C41: =Dashboard!O3 -> 42.5 | D41: 10-12
B42: Set 3 | C42: =Dashboard!O3 -> 42.5 | D42: 10-12
A44: Seated Cable Row | B44: Set 1 | C44: 32 | D44: 10-12
B45: Set 2 | C45: 32 | D45: 10-12
B46: Set 3 | C46: 32 | D46: 10-12
A48: Strict Row | B48: Set 1 | C48: =Dashboard!P3 -> 42.5 | D48: 10-12
B49: Set 2 | C49: =Dashboard!P3 -> 42.5 | D49: 10-12
B50: Set 3 | C50: =Dashboard!P3 -> 42.5 | D50: 10-12
A52: Hammer Curl | B52: Set 1 | C52: =Dashboard!Q3 -> 42.5 | D52: 10-12
B53: Set 2 | C53: =Dashboard!Q3 -> 42.5 | D53: 10-12
...

Sheet Week 2
A1: Week 2
A3: TUESDAY – PUSH
A4: Exercise | B4: Working Set | C4: Target Kg | D4: Reps | E4: RPE | F4: Notes
A5: Back Squat | B5: Set 1 | C5: =Dashboard!B30 -> 80 | D5: 6
B6: Set 2 | C6: =Dashboard!B30 -> 80 | D6: 6
B7: Set 3 | C7: =Dashboard!B30 -> 80 | D7: 6
A9: Bench Press | B9: Set 1 | C9: =Dashboard!C30 -> 35 | D9: 6
B10: Set 2 | C10: =Dashboard!C30 -> 35 | D10: 6
B11: Set 3 | C11: =Dashboard!C30 -> 35 | D11: 6
A13: Standing OHP | B13: Set 1 | C13: =Dashboard!D30 -> 25 | D13: 6
B14: Set 2 | C14: =Dashboard!D30 -> 25 | D14: 6
B15: Set 3 | C15: =Dashboard!D30 -> 25 | D15: 6
A17: Leg Extension | B17: Set 1 | C17: =Dashboard!K4 -> 45 | D17: 10-12
B18: Set 2 | C18: =Dashboard!K4 -> 45 | D18: 10-12
B19: Set 3 | C19: =Dashboard!K4 -> 45 | D19: 10-12
A21: Incline Pec Fly | B21: Set 1 | C21: =Dashboard!L4 -> 45 | D21: 10-12
B22: Set 2 | C22: =Dashboard!L4 -> 45 | D22: 10-12
B23: Set 3 | C23: =Dashboard!L4 -> 45 | D23: 10-12
A25: Lateral Raise | B25: Set 1 | C25: =Dashboard!M4 -> 45 | D25: 10-12
B26: Set 2 | C26: =Dashboard!M4 -> 45 | D26: 10-12
B27: Set 3 | C27: =Dashboard!M4 -> 45 | D27: 10-12
A30: THURSDAY – PULL
A31: Exercise | B31: Working Set | C31: Target Kg | D31: Reps | E31: RPE | F31: Notes
A32: Deadlift | B32: Set 1 | C32: =Dashboard!E30 -> 110 | D32: 6
B33: Set 2 | C33: =Dashboard!E30 -> 110 | D33: 6
B34: Set 3 | C34: =Dashboard!E30 -> 110 | D34: 6
A36: Hammer Grip Row | B36: Set 1 | C36: =Dashboard!N4 -> 45 | D36: 10-12
B37: Set 2 | C37: =Dashboard!N4 -> 45 | D37: 10-12
B38: Set 3 | C38: =Dashboard!N4 -> 45 | D38: 10-12
A40: Pronated Lat Pulldown | B40: Set 1 | C40: =Dashboard!O4 -> 45 | D40: 10-12
B41: Set 2 | C41: =Dashboard!O4 -> 45 | D41: 10-12
B42: Set 3 | C42: =Dashboard!O4 -> 45 | D42: 10-12
A44: Seated Cable Row | B44: Set 1 | D44: 10-12
B45: Set 2 | D45: 10-12
B46: Set 3 | D46: 10-12
A48: Strict Row | B48: Set 1 | C48: =Dashboard!P4 -> 45 | D48: 10-12
B49: Set 2 | C49: =Dashboard!P4 -> 45 | D49: 10-12
B50: Set 3 | C50: =Dashboard!P4 -> 45 | D50: 10-12
A52: Hammer Curl | B52: Set 1 | C52: =Dashboard!Q4 -> 45 | D52: 10-12
B53: Set 2 | C53: =Dashboard!Q4 -> 45 | D53: 10-12
...

Sheet Week 3
A1: Week 3
A3: TUESDAY – PUSH
A4: Exercise | B4: Working Set | C4: Target Kg | D4: Reps | E4: RPE | F4: Notes
A5: Back Squat | B5: Set 1 | C5: =Dashboard!B32 -> 80 | D5: 5
B6: Set 2 | C6: =Dashboard!B32 -> 80 | D6: 5
B7: Set 3 | C7: =Dashboard!B32 -> 80 | D7: 5
A9: Bench Press | B9: Set 1 | C9: =Dashboard!C32 -> 35 | D9: 5
B10: Set 2 | C10: =Dashboard!C32 -> 35 | D10: 5
B11: Set 3 | C11: =Dashboard!C32 -> 35 | D11: 5
A13: Standing OHP | B13: Set 1 | C13: =Dashboard!D32 -> 25 | D13: 5
B14: Set 2 | C14: =Dashboard!D32 -> 25 | D14: 5
B15: Set 3 | C15: =Dashboard!D32 -> 25 | D15: 5
A17: Leg Extension | B17: Set 1 | C17: =Dashboard!K5 -> 45 | D17: 10-12
B18: Set 2 | C18: =Dashboard!K5 -> 45 | D18: 10-12
B19: Set 3 | C19: =Dashboard!K5 -> 45 | D19: 10-12
A21: Incline Pec Fly | B21: Set 1 | C21: =Dashboard!L5 -> 45 | D21: 10-12
B22: Set 2 | C22: =Dashboard!L5 -> 45 | D22: 10-12
B23: Set 3 | C23: =Dashboard!L5 -> 45 | D23: 10-12
A25: Lateral Raise | B25: Set 1 | C25: =Dashboard!M5 -> 45 | D25: 10-12
B26: Set 2 | C26: =Dashboard!M5 -> 45 | D26: 10-12
B27: Set 3 | C27: =Dashboard!M5 -> 45 | D27: 10-12
A30: THURSDAY – PULL
A31: Exercise | B31: Working Set | C31: Target Kg | D31: Reps | E31: RPE | F31: Notes
A32: Deadlift | B32: Set 1 | C32: =Dashboard!E32 -> 110 | D32: 5
B33: Set 2 | C33: =Dashboard!E32 -> 110 | D33: 5
B34: Set 3 | C34: =Dashboard!E32 -> 110 | D34: 5
A36: Hammer Grip Row | B36: Set 1 | C36: =Dashboard!N5 -> 45 | D36: 10-12
B37: Set 2 | C37: =Dashboard!N5 -> 45 | D37: 10-12
B38: Set 3 | C38: =Dashboard!N5 -> 45 | D38: 10-12
A40: Pronated Lat Pulldown | B40: Set 1 | C40: =Dashboard!O5 -> 45 | D40: 10-12
B41: Set 2 | C41: =Dashboard!O5 -> 45 | D41: 10-12
B42: Set 3 | C42: =Dashboard!O5 -> 45 | D42: 10-12
A44: Seated Cable Row | B44: Set 1 | D44: 10-12
B45: Set 2 | D45: 10-12
B46: Set 3 | D46: 10-12
A48: Strict Row | B48: Set 1 | C48: =Dashboard!P5 -> 45 | D48: 10-12
B49: Set 2 | C49: =Dashboard!P5 -> 45 | D49: 10-12
B50: Set 3 | C50: =Dashboard!P5 -> 45 | D50: 10-12
A52: Hammer Curl | B52: Set 1 | C52: =Dashboard!Q5 -> 45 | D52: 10-12
B53: Set 2 | C53: =Dashboard!Q5 -> 45 | D53: 10-12
...

Sheet Week 4
A1: Week 4
A3: TUESDAY – PUSH
A4: Exercise | B4: Working Set | C4: Target Kg | D4: Reps | E4: RPE | F4: Notes
A5: Back Squat | B5: Set 1 | C5: =Dashboard!B33 -> 85 | D5: 3
B6: Set 2 | C6: =Dashboard!B33 -> 85 | D6: 3
B7: Set 3 | C7: =Dashboard!B33 -> 85 | D7: 3
B8: Set 4 | C8: =Dashboard!B33 -> 85 | D8: 3
A10: Bench Press | B10: Set 1 | C10: =Dashboard!C33 -> 35 | D10: 3
B11: Set 2 | C11: =Dashboard!C33 -> 35 | D11: 3
B12: Set 3 | C12: =Dashboard!C33 -> 35 | D12: 3
B13: Set 4 | C13: =Dashboard!C33 -> 35 | D13: 3
A15: Standing OHP | B15: Set 1 | C15: =Dashboard!D33 -> 25 | D15: 3
B16: Set 2 | C16: =Dashboard!D33 -> 25 | D16: 3
B17: Set 3 | C17: =Dashboard!D33 -> 25 | D17: 3
B18: Set 4 | C18: =Dashboard!D33 -> 25 | D18: 3
A20: Leg Extension | B20: Set 1 | C20: =Dashboard!K6 -> 47.5 | D20: 10-12
B21: Set 2 | C21: =Dashboard!K6 -> 47.5 | D21: 10-12
B22: Set 3 | C22: =Dashboard!K6 -> 47.5 | D22: 10-12
A24: Incline Pec Fly | B24: Set 1 | C24: =Dashboard!L6 -> 47.5 | D24: 10-12
B25: Set 2 | C25: =Dashboard!L6 -> 47.5 | D25: 10-12
B26: Set 3 | C26: =Dashboard!L6 -> 47.5 | D26: 10-12
A28: Lateral Raise | B28: Set 1 | C28: =Dashboard!M6 -> 47.5 | D28: 10-12
B29: Set 2 | C29: =Dashboard!M6 -> 47.5 | D29: 10-12
B30: Set 3 | C30: =Dashboard!M6 -> 47.5 | D30: 10-12
A33: THURSDAY – PULL
A34: Exercise | B34: Working Set | C34: Target Kg | D34: Reps | E34: RPE | F34: Notes
A35: Deadlift | B35: Set 1 | C35: =Dashboard!E33 -> 115 | D35: 3
B36: Set 2 | C36: =Dashboard!E33 -> 115 | D36: 3
B37: Set 3 | C37: =Dashboard!E33 -> 115 | D37: 3
B38: Set 4 | C38: =Dashboard!E33 -> 115 | D38: 3
A40: Hammer Grip Row | B40: Set 1 | C40: =Dashboard!N6 -> 47.5 | D40: 10-12
B41: Set 2 | C41: =Dashboard!N6 -> 47.5 | D41: 10-12
B42: Set 3 | C42: =Dashboard!N6 -> 47.5 | D42: 10-12
A44: Pronated Lat Pulldown | B44: Set 1 | C44: =Dashboard!O6 -> 47.5 | D44: 10-12
B45: Set 2 | C45: =Dashboard!O6 -> 47.5 | D45: 10-12
B46: Set 3 | C46: =Dashboard!O6 -> 47.5 | D46: 10-12
A48: Seated Cable Row | B48: Set 1 | D48: 10-12
B49: Set 2 | D49: 10-12
B50: Set 3 | D50: 10-12
A52: Strict Row | B52: Set 1 | C52: =Dashboard!P6 -> 47.5 | D52: 10-12
...

Sheet Week 5
A1: Week 5
A3: TUESDAY – PUSH
A4: Exercise | B4: Working Set | C4: Target Kg | D4: Reps | E4: RPE | F4: Notes
A5: Back Squat | B5: Set 1 | C5: =Dashboard!B35 -> 85 | D5: 12
B6: Set 2 | C6: =Dashboard!B35 -> 85 | D6: 12
B7: Set 3 | C7: =Dashboard!B35 -> 85 | D7: 12
A9: Bench Press | B9: Set 1 | C9: =Dashboard!C35 -> 35 | D9: 12
B10: Set 2 | C10: =Dashboard!C35 -> 35 | D10: 12
B11: Set 3 | C11: =Dashboard!C35 -> 35 | D11: 12
A13: Standing OHP | B13: Set 1 | C13: =Dashboard!D35 -> 25 | D13: 12
B14: Set 2 | C14: =Dashboard!D35 -> 25 | D14: 12
B15: Set 3 | C15: =Dashboard!D35 -> 25 | D15: 12
A17: Leg Extension | B17: Set 1 | C17: =Dashboard!K3 -> 42.5 | D17: 10-12
B18: Set 2 | C18: =Dashboard!K3 -> 42.5 | D18: 10-12
B19: Set 3 | C19: =Dashboard!K3 -> 42.5 | D19: 10-12
A21: Incline Pec Fly | B21: Set 1 | C21: =Dashboard!L3 -> 42.5 | D21: 10-12
B22: Set 2 | C22: =Dashboard!L3 -> 42.5 | D22: 10-12
B23: Set 3 | C23: =Dashboard!L3 -> 42.5 | D23: 10-12
A25: Lateral Raise | B25: Set 1 | C25: =Dashboard!M3 -> 42.5 | D25: 10-12
B26: Set 2 | C26: =Dashboard!M3 -> 42.5 | D26: 10-12
B27: Set 3 | C27: =Dashboard!M3 -> 42.5 | D27: 10-12
A30: THURSDAY – PULL
A31: Exercise | B31: Working Set | C31: Target Kg | D31: Reps | E31: RPE | F31: Notes
A32: Deadlift | B32: Set 1 | C32: =Dashboard!E35 -> 120 | D32: 12
B33: Set 2 | C33: =Dashboard!E35 -> 120 | D33: 12
B34: Set 3 | C34: =Dashboard!E35 -> 120 | D34: 12
A36: Hammer Grip Row | B36: Set 1 | C36: =Dashboard!N3 -> 42.5 | D36: 10-12
B37: Set 2 | C37: =Dashboard!N3 -> 42.5 | D37: 10-12
B38: Set 3 | C38: =Dashboard!N3 -> 42.5 | D38: 10-12
A40: Pronated Lat Pulldown | B40: Set 1 | C40: =Dashboard!O3 -> 42.5 | D40: 10-12
B41: Set 2 | C41: =Dashboard!O3 -> 42.5 | D41: 10-12
B42: Set 3 | C42: =Dashboard!O3 -> 42.5 | D42: 10-12
A44: Seated Cable Row | B44: Set 1 | D44: 10-12
B45: Set 2 | D45: 10-12
B46: Set 3 | D46: 10-12
A48: Strict Row | B48: Set 1 | C48: =Dashboard!P3 -> 42.5 | D48: 10-12
B49: Set 2 | C49: =Dashboard!P3 -> 42.5 | D49: 10-12
B50: Set 3 | C50: =Dashboard!P3 -> 42.5 | D50: 10-12
A52: Hammer Curl | B52: Set 1 | C52: =Dashboard!Q3 -> 42.5 | D52: 10-12
B53: Set 2 | C53: =Dashboard!Q3 -> 42.5 | D53: 10-12
...

Sheet Week 6
A1: Week 6
A3: TUESDAY – PUSH
A4: Exercise | B4: Working Set | C4: Target Kg | D4: Reps | E4: RPE | F4: Notes
A5: Back Squat | B5: Set 1 | C5: =Dashboard!B23 -> 60 | D5: 8
B6: Set 2 | C6: =Dashboard!B23 -> 60 | D6: 8
B7: Set 3 | C7: =Dashboard!B23 -> 60 | D7: 8
A9: Bench Press | B9: Set 1 | C9: =Dashboard!C23 -> 25 | D9: 8
B10: Set 2 | C10: =Dashboard!C23 -> 25 | D10: 8
B11: Set 3 | C11: =Dashboard!C23 -> 25 | D11: 8
A13: Standing OHP | B13: Set 1 | C13: =Dashboard!D23 -> 20 | D13: 8
B14: Set 2 | C14: =Dashboard!D23 -> 20 | D14: 8
B15: Set 3 | C15: =Dashboard!D23 -> 20 | D15: 8
A17: Leg Extension | B17: Set 1 | C17: =Dashboard!K5 -> 45 | D17: 10-12
B18: Set 2 | C18: =Dashboard!K5 -> 45 | D18: 10-12
B19: Set 3 | C19: =Dashboard!K5 -> 45 | D19: 10-12
A21: Incline Pec Fly | B21: Set 1 | C21: =Dashboard!L5 -> 45 | D21: 10-12
B22: Set 2 | C22: =Dashboard!L5 -> 45 | D22: 10-12
B23: Set 3 | C23: =Dashboard!L5 -> 45 | D23: 10-12
A25: Lateral Raise | B25: Set 1 | C25: =Dashboard!M5 -> 45 | D25: 10-12
B26: Set 2 | C26: =Dashboard!M5 -> 45 | D26: 10-12
B27: Set 3 | C27: =Dashboard!M5 -> 45 | D27: 10-12
A30: THURSDAY – PULL
A31: Exercise | B31: Working Set | C31: Target Kg | D31: Reps | E31: RPE | F31: Notes
A32: Deadlift | B32: Set 1 | C32: =Dashboard!E23 -> 80 | D32: 8
B33: Set 2 | C33: =Dashboard!E23 -> 80 | D33: 8
B34: Set 3 | C34: =Dashboard!E23 -> 80 | D34: 8
A36: Hammer Grip Row | B36: Set 1 | C36: =Dashboard!N5 -> 45 | D36: 10-12
B37: Set 2 | C37: =Dashboard!N5 -> 45 | D37: 10-12
B38: Set 3 | C38: =Dashboard!N5 -> 45 | D38: 10-12
A40: Pronated Lat Pulldown | B40: Set 1 | C40: =Dashboard!O5 -> 45 | D40: 10-12
B41: Set 2 | C41: =Dashboard!O5 -> 45 | D41: 10-12
B42: Set 3 | C42: =Dashboard!O5 -> 45 | D42: 10-12
A44: Seated Cable Row | B44: Set 1 | D44: 10-12
B45: Set 2 | D45: 10-12
B46: Set 3 | D46: 10-12
A48: Strict Row | B48: Set 1 | C48: =Dashboard!P5 -> 45 | D48: 10-12
B49: Set 2 | C49: =Dashboard!P5 -> 45 | D49: 10-12
B50: Set 3 | C50: =Dashboard!P5 -> 45 | D50: 10-12
A52: Hammer Curl | B52: Set 1 | C52: =Dashboard!Q5 -> 45 | D52: 10-12
B53: Set 2 | C53: =Dashboard!Q5 -> 45 | D53: 10-12
...

Sheet Week 7
A1: Week 7
A3: TUESDAY – PUSH
A4: Exercise | B4: Working Set | C4: Target Kg | D4: Reps | E4: RPE | F4: Notes
A5: Back Squat | B5: Set 1 | C5: =Dashboard!B24 -> 65 | D5: 8
B6: Set 2 | C6: =Dashboard!B24 -> 65 | D6: 8
B7: Set 3 | C7: =Dashboard!B24 -> 65 | D7: 8
A9: Bench Press | B9: Set 1 | C9: =Dashboard!C24 -> 30 | D9: 8
B10: Set 2 | C10: =Dashboard!C24 -> 30 | D10: 8
B11: Set 3 | C11: =Dashboard!C24 -> 30 | D11: 8
A13: Standing OHP | B13: Set 1 | C13: =Dashboard!D24 -> 20 | D13: 8
B14: Set 2 | C14: =Dashboard!D24 -> 20 | D14: 8
B15: Set 3 | C15: =Dashboard!D24 -> 20 | D15: 8
A17: Leg Extension | B17: Set 1 | C17: =Dashboard!K4 -> 45 | D17: 10-12
B18: Set 2 | C18: =Dashboard!K4 -> 45 | D18: 10-12
B19: Set 3 | C19: =Dashboard!K4 -> 45 | D19: 10-12
A21: Incline Pec Fly | B21: Set 1 | C21: =Dashboard!L4 -> 45 | D21: 10-12
B22: Set 2 | C22: =Dashboard!L4 -> 45 | D22: 10-12
B23: Set 3 | C23: =Dashboard!L4 -> 45 | D23: 10-12
A25: Lateral Raise | B25: Set 1 | C25: =Dashboard!M4 -> 45 | D25: 10-12
B26: Set 2 | C26: =Dashboard!M4 -> 45 | D26: 10-12
B27: Set 3 | C27: =Dashboard!M4 -> 45 | D27: 10-12
A30: THURSDAY – PULL
A31: Exercise | B31: Working Set | C31: Target Kg | D31: Reps | E31: RPE | F31: Notes
A32: Deadlift | B32: Set 1 | C32: =Dashboard!E24 -> 90 | D32: 8
B33: Set 2 | C33: =Dashboard!E24 -> 90 | D33: 8
B34: Set 3 | C34: =Dashboard!E24 -> 90 | D34: 8
A36: Hammer Grip Row | B36: Set 1 | C36: =Dashboard!N4 -> 45 | D36: 10-12
B37: Set 2 | C37: =Dashboard!N4 -> 45 | D37: 10-12
B38: Set 3 | C38: =Dashboard!N4 -> 45 | D38: 10-12
A40: Pronated Lat Pulldown | B40: Set 1 | C40: =Dashboard!O4 -> 45 | D40: 10-12
B41: Set 2 | C41: =Dashboard!O4 -> 45 | D41: 10-12
B42: Set 3 | C42: =Dashboard!O4 -> 45 | D42: 10-12
A44: Seated Cable Row | B44: Set 1 | D44: 10-12
B45: Set 2 | D45: 10-12
B46: Set 3 | D46: 10-12
A48: Strict Row | B48: Set 1 | C48: =Dashboard!P4 -> 45 | D48: 10-12
B49: Set 2 | C49: =Dashboard!P4 -> 45 | D49: 10-12
B50: Set 3 | C50: =Dashboard!P4 -> 45 | D50: 10-12
A52: Hammer Curl | B52: Set 1 | C52: =Dashboard!Q4 -> 45 | D52: 10-12
B53: Set 2 | C53: =Dashboard!Q4 -> 45 | D53: 10-12
...

Sheet Week 8
A1: Week 8
A3: TUESDAY – PUSH
A4: Exercise | B4: Working Set | C4: Target Kg | D4: Reps | E4: RPE | F4: Notes
A5: Back Squat | B5: Set 1 | C5: =Dashboard!B24 -> 65 | D5: 6
B6: Set 2 | C6: =Dashboard!B24 -> 65 | D6: 6
B7: Set 3 | C7: =Dashboard!B24 -> 65 | D7: 6
A9: Bench Press | B9: Set 1 | C9: =Dashboard!C24 -> 30 | D9: 6
B10: Set 2 | C10: =Dashboard!C24 -> 30 | D10: 6
B11: Set 3 | C11: =Dashboard!C24 -> 30 | D11: 6
A13: Standing OHP | B13: Set 1 | C13: =Dashboard!D24 -> 20 | D13: 6
B14: Set 2 | C14: =Dashboard!D24 -> 20 | D14: 6
B15: Set 3 | C15: =Dashboard!D24 -> 20 | D15: 6
A17: Leg Extension | B17: Set 1 | C17: =Dashboard!K5 -> 45 | D17: 10-12
B18: Set 2 | C18: =Dashboard!K5 -> 45 | D18: 10-12
B19: Set 3 | C19: =Dashboard!K5 -> 45 | D19: 10-12
A21: Incline Pec Fly | B21: Set 1 | C21: =Dashboard!L5 -> 45 | D21: 10-12
B22: Set 2 | C22: =Dashboard!L5 -> 45 | D22: 10-12
B23: Set 3 | C23: =Dashboard!L5 -> 45 | D23: 10-12
A25: Lateral Raise | B25: Set 1 | C25: =Dashboard!M5 -> 45 | D25: 10-12
B26: Set 2 | C26: =Dashboard!M5 -> 45 | D26: 10-12
B27: Set 3 | C27: =Dashboard!M5 -> 45 | D27: 10-12
A30: THURSDAY – PULL
A31: Exercise | B31: Working Set | C31: Target Kg | D31: Reps | E31: RPE | F31: Notes
A32: Deadlift | B32: Set 1 | C32: =Dashboard!E24 -> 90 | D32: 6
B33: Set 2 | C33: =Dashboard!E24 -> 90 | D33: 6
B34: Set 3 | C34: =Dashboard!E24 -> 90 | D34: 6
A36: Hammer Grip Row | B36: Set 1 | C36: =Dashboard!N5 -> 45 | D36: 10-12
B37: Set 2 | C37: =Dashboard!N5 -> 45 | D37: 10-12
B38: Set 3 | C38: =Dashboard!N5 -> 45 | D38: 10-12
A40: Pronated Lat Pulldown | B40: Set 1 | C40: =Dashboard!O5 -> 45 | D40: 10-12
B41: Set 2 | C41: =Dashboard!O5 -> 45 | D41: 10-12
B42: Set 3 | C42: =Dashboard!O5 -> 45 | D42: 10-12
A44: Seated Cable Row | B44: Set 1 | D44: 10-12
B45: Set 2 | D45: 10-12
B46: Set 3 | D46: 10-12
A48: Strict Row | B48: Set 1 | C48: =Dashboard!P5 -> 45 | D48: 10-12
B49: Set 2 | C49: =Dashboard!P5 -> 45 | D49: 10-12
B50: Set 3 | C50: =Dashboard!P5 -> 45 | D50: 10-12
A52: Hammer Curl | B52: Set 1 | C52: =Dashboard!Q5 -> 45 | D52: 10-12
B53: Set 2 | C53: =Dashboard!Q5 -> 45 | D53: 10-12
...

Sheet Week 9
A1: Week 9
A3: TUESDAY – PUSH
A4: Exercise | B4: Working Set | C4: Target Kg | D4: Reps | E4: RPE | F4: Notes
A5: Back Squat | B5: Set 1 | C5: =Dashboard!B33 -> 85 | D5: 5
B6: Set 2 | C6: =Dashboard!B33 -> 85 | D6: 5
B7: Set 3 | C7: =Dashboard!B33 -> 85 | D7: 5
A9: Bench Press | B9: Set 1 | C9: =Dashboard!C33 -> 35 | D9: 5
B10: Set 2 | C10: =Dashboard!C33 -> 35 | D10: 5
B11: Set 3 | C11: =Dashboard!C33 -> 35 | D11: 5
A13: Standing OHP | B13: Set 1 | C13: =Dashboard!D33 -> 25 | D13: 5
B14: Set 2 | C14: =Dashboard!D33 -> 25 | D14: 5
B15: Set 3 | C15: =Dashboard!D33 -> 25 | D15: 5
A17: Leg Extension | B17: Set 1 | C17: =Dashboard!K6 -> 47.5 | D17: 10-12
B18: Set 2 | C18: =Dashboard!K6 -> 47.5 | D18: 10-12
B19: Set 3 | C19: =Dashboard!K6 -> 47.5 | D19: 10-12
A21: Incline Pec Fly | B21: Set 1 | C21: =Dashboard!L6 -> 47.5 | D21: 10-12
B22: Set 2 | C22: =Dashboard!L6 -> 47.5 | D22: 10-12
B23: Set 3 | C23: =Dashboard!L6 -> 47.5 | D23: 10-12
A25: Lateral Raise | B25: Set 1 | C25: =Dashboard!M6 -> 47.5 | D25: 10-12
B26: Set 2 | C26: =Dashboard!M6 -> 47.5 | D26: 10-12
B27: Set 3 | C27: =Dashboard!M6 -> 47.5 | D27: 10-12
A30: THURSDAY – PULL
A31: Exercise | B31: Working Set | C31: Target Kg | D31: Reps | E31: RPE | F31: Notes
A32: Deadlift | B32: Set 1 | C32: =Dashboard!E33 -> 115 | D32: 5
B33: Set 2 | C33: =Dashboard!E33 -> 115 | D33: 5
B34: Set 3 | C34: =Dashboard!E33 -> 115 | D34: 5
A36: Hammer Grip Row | B36: Set 1 | C36: =Dashboard!N6 -> 47.5 | D36: 10-12
B37: Set 2 | C37: =Dashboard!N6 -> 47.5 | D37: 10-12
B38: Set 3 | C38: =Dashboard!N6 -> 47.5 | D38: 10-12
A40: Pronated Lat Pulldown | B40: Set 1 | C40: =Dashboard!O6 -> 47.5 | D40: 10-12
B41: Set 2 | C41: =Dashboard!O6 -> 47.5 | D41: 10-12
B42: Set 3 | C42: =Dashboard!O6 -> 47.5 | D42: 10-12
A44: Seated Cable Row | B44: Set 1 | D44: 10-12
B45: Set 2 | D45: 10-12
B46: Set 3 | D46: 10-12
A48: Strict Row | B48: Set 1 | C48: =Dashboard!P6 -> 47.5 | D48: 10-12
B49: Set 2 | C49: =Dashboard!P6 -> 47.5 | D49: 10-12
B50: Set 3 | C50: =Dashboard!P6 -> 47.5 | D50: 10-12
A52: Hammer Curl | B52: Set 1 | C52: =Dashboard!Q6 -> 47.5 | D52: 10-12
B53: Set 2 | C53: =Dashboard!Q6 -> 47.5 | D53: 10-12
...

Sheet Week 10
A1: Week 10
A3: TUESDAY – PUSH
A4: Exercise | B4: Working Set | C4: Target Kg | D4: Reps | E4: RPE | F4: Notes
A5: Back Squat | B5: Set 1 | C5: =Dashboard!B36 -> 90 | D5: 3
B6: Set 2 | C6: =Dashboard!B36 -> 90 | D6: 3
B7: Set 3 | C7: =Dashboard!B36 -> 90 | D7: 3
B8: Set 4 | C8: =Dashboard!B36 -> 90 | D8: 3
A10: Bench Press | B10: Set 1 | C10: =Dashboard!C36 -> 40 | D10: 3
B11: Set 2 | C11: =Dashboard!C36 -> 40 | D11: 3
B12: Set 3 | C12: =Dashboard!C36 -> 40 | D12: 3
B13: Set 4 | C13: =Dashboard!C36 -> 40 | D13: 3
A15: Standing OHP | B15: Set 1 | C15: =Dashboard!D36 -> 30 | D15: 3
B16: Set 2 | C16: =Dashboard!D36 -> 30 | D16: 3
B17: Set 3 | C17: =Dashboard!D36 -> 30 | D17: 3
B18: Set 4 | C18: =Dashboard!D36 -> 30 | D18: 3
A20: Leg Extension | B20: Set 1 | C20: =Dashboard!K7 -> 47.5 | D20: 10-12
B21: Set 2 | C21: =Dashboard!K7 -> 47.5 | D21: 10-12
B22: Set 3 | C22: =Dashboard!K7 -> 47.5 | D22: 10-12
A24: Incline Pec Fly | B24: Set 1 | C24: =Dashboard!L7 -> 47.5 | D24: 10-12
B25: Set 2 | C25: =Dashboard!L7 -> 47.5 | D25: 10-12
B26: Set 3 | C26: =Dashboard!L7 -> 47.5 | D26: 10-12
A28: Lateral Raise | B28: Set 1 | C28: =Dashboard!M7 -> 47.5 | D28: 10-12
B29: Set 2 | C29: =Dashboard!M7 -> 47.5 | D29: 10-12
B30: Set 3 | C30: =Dashboard!M7 -> 47.5 | D30: 10-12
A33: THURSDAY – PULL
A34: Exercise | B34: Working Set | C34: Target Kg | D34: Reps | E34: RPE | F34: Notes
A35: Deadlift | B35: Set 1 | C35: =Dashboard!E36 -> 120 | D35: 3
B36: Set 2 | C36: =Dashboard!E36 -> 120 | D36: 3
B37: Set 3 | C37: =Dashboard!E36 -> 120 | D37: 3
B38: Set 4 | C38: =Dashboard!E36 -> 120 | D38: 3
A40: Hammer Grip Row | B40: Set 1 | C40: =Dashboard!N7 -> 47.5 | D40: 10-12
B41: Set 2 | C41: =Dashboard!N7 -> 47.5 | D41: 10-12
B42: Set 3 | C42: =Dashboard!N7 -> 47.5 | D42: 10-12
A44: Pronated Lat Pulldown | B44: Set 1 | C44: =Dashboard!O7 -> 47.5 | D44: 10-12
B45: Set 2 | C45: =Dashboard!O7 -> 47.5 | D45: 10-12
B46: Set 3 | C46: =Dashboard!O7 -> 47.5 | D46: 10-12
A48: Seated Cable Row | B48: Set 1 | D48: 10-12
B49: Set 2 | D49: 10-12
B50: Set 3 | D50: 10-12
A52: Strict Row | B52: Set 1 | C52: =Dashboard!P7 -> 47.5 | D52: 10-12
...

Sheet Week 11
A1: Week 11
A3: TUESDAY – PUSH
A4: Exercise | B4: Working Set | C4: Target Kg | D4: Reps | E4: RPE | F4: Notes
A5: Back Squat | B5: Set 1 | C5: =Dashboard!B37 -> 90 | D5: 12
B6: Set 2 | C6: =Dashboard!B37 -> 90 | D6: 12
B7: Set 3 | C7: =Dashboard!B37 -> 90 | D7: 12
A9: Bench Press | B9: Set 1 | C9: =Dashboard!C37 -> 40 | D9: 12
B10: Set 2 | C10: =Dashboard!C37 -> 40 | D10: 12
B11: Set 3 | C11: =Dashboard!C37 -> 40 | D11: 12
A13: Standing OHP | B13: Set 1 | C13: =Dashboard!D37 -> 30 | D13: 12
B14: Set 2 | C14: =Dashboard!D37 -> 30 | D14: 12
B15: Set 3 | C15: =Dashboard!D37 -> 30 | D15: 12
A17: Leg Extension | B17: Set 1 | C17: =Dashboard!K3 -> 42.5 | D17: 10-12
B18: Set 2 | C18: =Dashboard!K3 -> 42.5 | D18: 10-12
B19: Set 3 | C19: =Dashboard!K3 -> 42.5 | D19: 10-12
A21: Incline Pec Fly | B21: Set 1 | C21: =Dashboard!L3 -> 42.5 | D21: 10-12
B22: Set 2 | C22: =Dashboard!L3 -> 42.5 | D22: 10-12
B23: Set 3 | C23: =Dashboard!L3 -> 42.5 | D23: 10-12
A25: Lateral Raise | B25: Set 1 | C25: =Dashboard!M3 -> 42.5 | D25: 10-12
B26: Set 2 | C26: =Dashboard!M3 -> 42.5 | D26: 10-12
B27: Set 3 | C27: =Dashboard!M3 -> 42.5 | D27: 10-12
A30: THURSDAY – PULL
A31: Exercise | B31: Working Set | C31: Target Kg | D31: Reps | E31: RPE | F31: Notes
A32: Deadlift | B32: Set 1 | C32: =Dashboard!E37 -> 125 | D32: 12
B33: Set 2 | C33: =Dashboard!E37 -> 125 | D33: 12
B34: Set 3 | C34: =Dashboard!E37 -> 125 | D34: 12
A36: Hammer Grip Row | B36: Set 1 | C36: =Dashboard!N3 -> 42.5 | D36: 10-12
B37: Set 2 | C37: =Dashboard!N3 -> 42.5 | D37: 10-12
B38: Set 3 | C38: =Dashboard!N3 -> 42.5 | D38: 10-12
A40: Pronated Lat Pulldown | B40: Set 1 | C40: =Dashboard!O3 -> 42.5 | D40: 10-12
B41: Set 2 | C41: =Dashboard!O3 -> 42.5 | D41: 10-12
B42: Set 3 | C42: =Dashboard!O3 -> 42.5 | D42: 10-12
A44: Seated Cable Row | B44: Set 1 | D44: 10-12
B45: Set 2 | D45: 10-12
B46: Set 3 | D46: 10-12
A48: Strict Row | B48: Set 1 | C48: =Dashboard!P3 -> 42.5 | D48: 10-12
B49: Set 2 | C49: =Dashboard!P3 -> 42.5 | D49: 10-12
B50: Set 3 | C50: =Dashboard!P3 -> 42.5 | D50: 10-12
A52: Hammer Curl | B52: Set 1 | C52: =Dashboard!Q3 -> 42.5 | D52: 10-12
B53: Set 2 | C53: =Dashboard!Q3 -> 42.5 | D53: 10-12
...

Sheet Week 12
A1: Week 12
A3: TUESDAY – PUSH
A4: Exercise | B4: Working Set | C4: Target Kg | D4: Reps | E4: RPE | F4: Notes
A5: Back Squat | B5: Set 1 | C5: =Dashboard!B38 -> 95 | D5: 8
B6: Set 2 | C6: =Dashboard!B38 -> 95 | D6: 8
B7: Set 3 | C7: =Dashboard!B38 -> 95 | D7: 8
A9: Bench Press | B9: Set 1 | C9: =Dashboard!C38 -> 40 | D9: 8
B10: Set 2 | C10: =Dashboard!C38 -> 40 | D10: 8
B11: Set 3 | C11: =Dashboard!C38 -> 40 | D11: 8
A13: Standing OHP | B13: Set 1 | C13: =Dashboard!D38 -> 30 | D13: 8
B14: Set 2 | C14: =Dashboard!D38 -> 30 | D14: 8
B15: Set 3 | C15: =Dashboard!D38 -> 30 | D15: 8
A17: Leg Extension | B17: Set 1 | C17: =Dashboard!K5 -> 45 | D17: 10-12
B18: Set 2 | C18: =Dashboard!K5 -> 45 | D18: 10-12
B19: Set 3 | C19: =Dashboard!K5 -> 45 | D19: 10-12
A21: Incline Pec Fly | B21: Set 1 | C21: =Dashboard!L5 -> 45 | D21: 10-12
B22: Set 2 | C22: =Dashboard!L5 -> 45 | D22: 10-12
B23: Set 3 | C23: =Dashboard!L5 -> 45 | D23: 10-12
A25: Lateral Raise | B25: Set 1 | C25: =Dashboard!M5 -> 45 | D25: 10-12
B26: Set 2 | C26: =Dashboard!M5 -> 45 | D26: 10-12
B27: Set 3 | C27: =Dashboard!M5 -> 45 | D27: 10-12
A30: THURSDAY – PULL
A31: Exercise | B31: Working Set | C31: Target Kg | D31: Reps | E31: RPE | F31: Notes
A32: Deadlift | B32: Set 1 | C32: =Dashboard!E38 -> 130 | D32: 8
B33: Set 2 | C33: =Dashboard!E38 -> 130 | D33: 8
B34: Set 3 | C34: =Dashboard!E38 -> 130 | D34: 8
A36: Hammer Grip Row | B36: Set 1 | C36: =Dashboard!N5 -> 45 | D36: 10-12
B37: Set 2 | C37: =Dashboard!N5 -> 45 | D37: 10-12
B38: Set 3 | C38: =Dashboard!N5 -> 45 | D38: 10-12
A40: Pronated Lat Pulldown | B40: Set 1 | C40: =Dashboard!O5 -> 45 | D40: 10-12
B41: Set 2 | C41: =Dashboard!O5 -> 45 | D41: 10-12
B42: Set 3 | C42: =Dashboard!O5 -> 45 | D42: 10-12
A44: Seated Cable Row | B44: Set 1 | D44: 10-12
B45: Set 2 | D45: 10-12
B46: Set 3 | D46: 10-12
A48: Strict Row | B48: Set 1 | C48: =Dashboard!P5 -> 45 | D48: 10-12
B49: Set 2 | C49: =Dashboard!P5 -> 45 | D49: 10-12
B50: Set 3 | C50: =Dashboard!P5 -> 45 | D50: 10-12
A52: Hammer Curl | B52: Set 1 | C52: =Dashboard!Q5 -> 45 | D52: 10-12
B53: Set 2 | C53: =Dashboard!Q5 -> 45 | D53: 10-12
...

Sheet Week 13
A1: Strength Test
